Workbook

Sheet 2026
A1: إيجاري | K1: 2026
A2: م | B2: المشروع | C2: الاسم | D2: الممثل القانوني | E2: الوحدة | F2: العنوان | G2: العقد من | H2: العقد الى | I2: تسجيل ضريبي | J2: الرقم القومي / الباسبور | K2: يناير | L2: فبراير | M2: مارس | N2: ابريل | O2: مايو | P2: يونيو | Q2: يوليو | R2: اغسطس | S2: سبتمبر | T2: اكتوبر | U2: نوفمبر | V2: ديسمبر | W2: الاجمالي | X2: ملاحظات | Y2: كود العقد | Z2: كود الوحدة | AA2: كود العميل | AB2: كود المشروع
A3: 1 | B3: بابل | C3: حسام حسن سنوسي | D3: يوسف حسن سنوسي | E3: محل | F3: شارع بابل الدقي 39 | G3: 45078 | H3: 46173 | J3: 29202162300777 | K3: 12705 | L3: 12705 | M3: 12705 | N3: 12705 | O3: 12705 | W3: =SUM(K3:V3) | Y3: T0001 | Z3: P01-S1 | AA3: C001 | AB3: P01
A4: 2 | B4: بابل | C4: صالون ايه ام Salon A M | D4: محمد ابراهيم موسى | E4: محل | F4: شارع بابل الدقي 39 | G4: 45778 | H4: 46142 | J4: 29206013100132 | K4: 30500 | L4: 30500 | M4: 30500 | N4: 30500 | W4: =SUM(K4:V4) | Y4: T0002 | Z4: P01-S2 | AA4: C002 | AB4: P01
A5: 3 | B5: بابل | C5: شركة الدقة للاستشارات الهندسية | D5: محمد احمد فراج | E5: ميزان 1/2 | F5: شارع بابل الدقي 39 | G5: 45432 | H5: 46526 | I5: 726-387-908 | J5: 28803262100597 | K5: 45100 | L5: 45100 | M5: 45100 | N5: 45100 | O5: 46603 | P5: 49610 | Q5: 49610 | R5: 49610 | W5: =SUM(K5:V5) | Y5: T0003 | Z5: P01-M1-2 | AA5: C003 | AB5: P01
A6: 4 | B6: بابل | C6: شركة العنوان للانتاج الفني | D6: نسرين احمد عثمان | E6: ميزان 3 | F6: شارع بابل الدقي 39 | G6: 45444 | H6: 46173 | J6: P10629999 | K6: 41800 | L6: 41800 | M6: 41800 | N6: 41800 | O6: 41800 | W6: =SUM(K6:V6) | Y6: T0004 | Z6: P01-M3 | AA6: C004 | AB6: P01
A7: 5 | B7: بابل | C7: شركة الدقة للاستشارات الهندسية | D7: محمد احمد فراج | E7: الدور الثاني | F7: شارع بابل الدقي 39 | G7: 45352 | H7: 46446 | I7: 726-387-908 | J7: 28803262100597 | K7: 83600 | L7: 83600 | M7: 91960 | N7: 91960 | O7: 91960 | P7: 91960 | Q7: 91960 | R7: 91960 | W7: =SUM(K7:V7) | Y7: T0005 | Z7: P01-F2 | AA7: C003 | AB7: P01
A8: 6 | B8: بابل | C8: شركة ديل اند بيك للتجارة الالكترونية | D8: وليد محمود مصطفى | E8: مكتب 42 | F8: شارع بابل الدقي 39 | G8: 45158 | H8: 46253 | I8: 557-627-516 | J8: 28407140102651 | K8: 30250 | L8: 30250 | M8: 30250 | N8: 30250 | O8: 30250 | P8: 30250 | Q8: 30250 | R8: 44090 | W8: =SUM(K8:V8) | Y8: T0006 | Z8: P01-O42 | AA8: C005 | AB8: P01
A9: 7 | B9: بابل | C9: مصطفى عثمان ابراهيم | D9: مصطفى عثمان ابراهيم | E9: مكتب 61 | F9: شارع بابل الدقي 39 | G9: 45017 | H9: 46112 | J9: 27004050101531 | K9: 24330 | L9: 24330 | M9: 24330 | W9: =SUM(K9:V9) | Y9: T0007 | Z9: P01-O61 | AA9: C006 | AB9: P01
A10: 8 | B10: محيي الدين | C10: شركة مستر تايلور | D10: احمد رشد قاسم | E10: ميزان 1 | F10: شارع محيي الدين ابو العز 30 | G10: 45139 | H10: 46965 | I10: 721-692-965 | J10: 27307022102338 | K10: 42350 | L10: 42350 | M10: 42350 | N10: 42350 | O10: 42350 | P10: 42350 | Q10: 42350 | R10: 46585 | W10: =SUM(K10:V10) | Y10: T0008 | Z10: P02-M1 | AA10: C007 | AB10: P02
A11: 9 | B11: محيي الدين | C11: شركة صحة سكان | D11: اشرف صلاح محمد | E11: ميزان 2 | F11: شارع محيي الدين ابو العز 30 | G11: 45242 | H11: 46337 | I11: 421-187-875 | J11: 25510030100193 | K11: 25410 | L11: 25410 | M11: 25410 | N11: 25410 | O11: 25410 | P11: 25410 | Q11: 25410 | R11: 25410 | W11: =SUM(K11:V11) | Y11: T0009 | Z11: P02-M2 | AA11: C008 | AB11: P02
A12: 10 | B12: محيي الدين | C12: شركة ستاف ارابيا | D12: اياد صبحي حافظ | E12: 202 | F12: شارع محيي الدين ابو العز 30 | G12: 45231 | H12: 46326 | I12: 567-354-873 | J12: N011661697 | K12: 46585 | L12: 46585 | M12: 46585 | N12: 46585 | O12: 46585 | P12: 46585 | Q12: 46585 | R12: 46585 | W12: =SUM(K12:V12) | Y12: T0010 | Z12: P02-202 | AA12: C009 | AB12: P02
A13: 11 | B13: محيي الدين | C13: علي فرغلي علي | D13: علي فرغلي علي | E13: 301 | F13: شارع محيي الدين ابو العز 30 | G13: 46143 | H13: 46507 | J13: 29705050200631 | K13: 22990 | L13: 22990 | M13: 22990 | N13: 22990 | O13: 37000 | P13: 37000 | Q13: 37000 | R13: 37000 | W13: =SUM(K13:V13) | Y13: T0011 | Z13: P02-301 | AA13: C010 | AB13: P02
A14: 12 | B14: محيي الدين | C14: دكتور شريف عزت عبد الخالق | D14: دكتور شريف عزت عبد الخالق | E14: 302 | F14: شارع محيي الدين ابو العز 30 | G14: 46143 | H14: 46507 | J14: 26211150101815 | K14: 35000 | L14: 35000 | M14: 35000 | N14: 35000 | O14: 38500 | P14: 38500 | Q14: 38500 | R14: 37500 | W14: =SUM(K14:V14) | Y14: T0012 | Z14: P02-302 | AA14: C011 | AB14: P02
A15: 13 | B15: محيي الدين | C15: شركة ايجل اي ميدل ايست | D15: اسلام محمد عبد الفتاح | E15: 303 | F15: شارع محيي الدين ابو العز 30 | G15: 45870 | H15: 46965 | I15: 730-874-532 | J15: 28910220100539 | K15: 43000 | L15: 43000 | M15: 43000 | N15: 43000 | O15: 43000 | P15: 43000 | Q15: 43000 | R15: 49450 | W15: =SUM(K15:V15) | Y15: T0013 | Z15: P02-303 | AA15: C012 | AB15: P02
A16: 14 | B16: محيي الدين | C16: شركة ايجل اي ميدل ايست | D16: اسلام محمد عبد الفتاح | E16: 304 | F16: شارع محيي الدين ابو العز 30 | G16: 45474 | H16: 46568 | I16: 730-874-532 | J16: 28910220100539 | K16: 25300 | L16: 25300 | M16: 25300 | N16: 25300 | O16: 25300 | P16: 25300 | Q16: 27830 | R16: 27830 | W16: =SUM(K16:V16) | Y16: T0014 | Z16: P02-304 | AA16: C012 | AB16: P02
A17: 15 | B17: محيي الدين | C17: دكتور ياسر خالد بادي محمد | D17: ياسر خالد بادي محمد | E17: 401 | F17: شارع محيي الدين ابو العز 30 | G17: 45668 | H17: 46397 | J17: 29010208800714 | K17: 36025 | L17: 37665 | M17: 37665 | N17: 37665 | O17: 37665 | P17: 37665 | Q17: 37665 | R17: 37665 | W17: =SUM(K17:V17) | Y17: T0015 | Z17: P02-401 | AA17: C013 | AB17: P02
A18: 16 | B18: محيي الدين | C18: دكتور عمرو هشام محمد | D18: عمرو هشام محمد | E18: 404 | F18: شارع محيي الدين ابو العز 30 | G18: 45292 | H18: 46387 | J18: 29009011320232 | K18: 30250 | L18: 30250 | M18: 30250 | N18: 30250 | O18: 30250 | P18: 30250 | Q18: 30250 | R18: 30250 | W18: =SUM(K18:V18) | Y18: T0016 | Z18: P02-404 | AA18: C014 | AB18: P02
A19: 17 | B19: محيي الدين | C19: د/ احمد محمد حسن - د/ دينا محمد سعيد | D19: د/ احمد محمد حسن - د/ دينا محمد سعيد | E19: 502 | F19: شارع محيي الدين ابو العز 30 | G19: 45170 | H19: 46265 | J19: 27404220102918 | K19: 19060 | L19: 19060 | M19: 19060 | N19: 19060 | O19: 19060 | P19: 19060 | Q19: 19060 | R19: 19060 | W19: =SUM(K19:V19) | Y19: T0017 | Z19: P02-502 | AA19: C015 | AB19: P02
A20: 18 | B20: محيي الدين | C20: د/ ياسمين جمال - د/ محمد خطاب | D20: ياسمين محمد جمال الدين - محمد حمدي محمد | E20: 503 | F20: شارع محيي الدين ابو العز 30 | G20: 45200 | H20: 46295 | J20: 28607270103607 | K20: 20570 | L20: 20570 | M20: 20570 | N20: 20570 | O20: 20570 | P20: 20570 | Q20: 20570 | R20: 20570 | W20: =SUM(K20:V20) | Y20: T0018 | Z20: P02-503 | AA20: C016 | AB20: P02
A21: 19 | B21: محيي الدين | C21: حمدي جمال حمدي | D21: حمدي جمال حمدي | E21: 504 | F21: شارع محيي الدين ابو العز 30 | G21: 45231 | H21: 46326 | J21: 30109182600357 | K21: 25410 | L21: 25410 | M21: 25410 | N21: 25410 | O21: 25410 | P21: 25410 | Q21: 25410 | R21: 25410 | W21: =SUM(K21:V21) | Y21: T0019 | Z21: P02-504 | AA21: C017 | AB21: P02
A22: 20 | B22: ابو بكر | C22: شركة موريشي للاستيراد والتصدير | D22: محمد مصطفى محمد | E22: ميزان 1 | F22: شارع ابو بكر الصديق 3 | G22: 45505 | H22: 46599 | I22: 578-907-399 | J22: 28206128800771 | K22: 40700 | L22: 40700 | M22: 40700 | N22: 40700 | O22: 40700 | P22: 40700 | Q22: 40700 | R22: 44770 | W22: =SUM(K22:V22) | Y22: T0020 | Z22: P03-M1 | AA22: C018 | AB22: P03
A23: 21 | B23: ابو بكر | C23: شركة تسفع لتطوير المهارات | D23: محمد مصطفى محمد | E23: ميزان 2 | F23: شارع ابو بكر الصديق 3 | G23: 45505 | H23: 46599 | I23: 765-044-404 | J23: 28206128800771 | K23: 40700 | L23: 40700 | M23: 40700 | N23: 40700 | O23: 40700 | P23: 40700 | Q23: 40700 | R23: 44770 | W23: =SUM(K23:V23) | Y23: T0021 | Z23: P03-M2 | AA23: C019 | AB23: P03
A24: 22 | B24: ابو بكر | C24: احمد هاشم احمد | D24: احمد هاشم احمد | E24: 102 | F24: شارع ابو بكر الصديق 3 | G24: 46204 | H24: 46568 | J24: P12786398 | K24: 17500 | L24: 17500 | M24: 17500 | N24: 17500 | O24: 17500 | P24: 17500 | Q24: 20000 | R24: 20000 | W24: =SUM(K24:V24) | Y24: T0022 | Z24: P03-102 | AA24: C020 | AB24: P03
A25: 23 | B25: ابو بكر | C25: عبد الرحمن هلال احمد | D25: عبد الرحمن هلال احمد | E25: 103 | F25: شارع ابو بكر الصديق 3 | G25: 45992 | H25: 46356 | J25: 29108131301515 | K25: 7000 | L25: 7000 | M25: 7000 | N25: 7000 | O25: 7000 | P25: 7000 | Q25: 7000 | R25: 7000 | W25: =SUM(K25:V25) | Y25: T0023 | Z25: P03-103 | AA25: C021 | AB25: P03
A26: 24 | B26: ابو بكر | C26: وليد عبد الرحمن عبد الكريم | D26: وليد عبد الرحمن عبد الكريم | E26: 104 | F26: شارع ابو بكر الصديق 3 | G26: 46204 | H26: 46568 | J26: X853069 | K26: 13000 | L26: 13000 | M26: 13000 | N26: 13000 | O26: 13000 | P26: 13000 | Q26: 15000 | R26: 15000 | W26: =SUM(K26:V26) | Y26: T0024 | Z26: P03-104 | AA26: C022 | AB26: P03
A27: 25 | B27: ابو بكر | C27: احمد هاشم احمد | D27: احمد هاشم احمد | E27: 105 | F27: شارع ابو بكر الصديق 3 | G27: 46204 | H27: 46568 | J27: P12786398 | K27: 13500 | L27: 13500 | M27: 13500 | N27: 13500 | O27: 13500 | P27: 13500 | Q27: 15000 | R27: 1000 | W27: =SUM(K27:V27) | Y27: T0025 | Z27: P03-105 | AA27: C020 | AB27: P03
A28: 26 | B28: ابو بكر | C28: محمد هلال احمد | D28: محمد هلال احمد | E28: 106 | F28: شارع ابو بكر الصديق 3 | G28: 45992 | H28: 46356 | J28: 28408191301751 | K28: 7000 | L28: 7000 | M28: 7000 | N28: 7000 | O28: 7000 | P28: 7000 | Q28: 7000 | R28: 7000 | W28: =SUM(K28:V28) | Y28: T0026 | Z28: P03-106 | AA28: C023 | AB28: P03
A29: 27 | B29: ابو بكر | C29: محمد هلال احمد | D29: محمد هلال احمد | E29: 107 | F29: شارع ابو بكر الصديق 3 | G29: 46204 | H29: 46568 | J29: 28408191301751 | K29: 6000 | L29: 6000 | M29: 6000 | N29: 6000 | O29: 6000 | P29: 8000 | Q29: 8000 | R29: 8000 | W29: =SUM(K29:V29) | Y29: T0027 | Z29: P03-107 | AA29: C023 | AB29: P03
A30: 28 | B30: ابو بكر | C30: محمد هلال احمد | D30: محمد هلال احمد | E30: 108 | F30: شارع ابو بكر الصديق 3 | G30: 46204 | H30: 46568 | J30: 28408191301751 | K30: 6000 | L30: 6000 | M30: 6000 | N30: 6000 | O30: 6000 | P30: 8000 | Q30: 8000 | R30: 8000 | W30: =SUM(K30:V30) | Y30: T0028 | Z30: P03-108 | AA30: C023 | AB30: P03
A31: 29 | B31: ابو بكر | C31: ارابيك في اي بي | D31: ليلى جمال شعبان | E31: 201 | F31: شارع ابو بكر الصديق 3 | G31: 45078 | H31: 46173 | J31: 29409202103248 | K31: 11495 | L31: 11495 | M31: 11495 | N31: 11495 | O31: 11495 | W31: =SUM(K31:V31) | Y31: T0029 | Z31: P03-201 | AA31: C024 | AB31: P03
A32: 30 | B32: ابو بكر | C32: د/ احمد وجدي عبد القادر | D32: احمد وجدي عبد القادر | E32: 202 | F32: شارع ابو بكر الصديق 3 | G32: 45901 | H32: 46265 | J32: 28509092104431 | K32: 16500 | L32: 16500 | M32: 16500 | N32: 16500 | O32: 16500 | P32: 16500 | Q32: 16500 | R32: 16500 | W32: =SUM(K32:V32) | Y32: T0030 | Z32: P03-202 | AA32: C025 | AB32: P03
A33: 31 | B33: ابو بكر | C33: د/ مصطفى مجدي عوض | D33: مصطفى مجدي عوض | E33: 204 | F33: شارع ابو بكر الصديق 3 | G33: 45839 | H33: 46203 | J33: 28910178800274 | K33: 12500 | L33: 12500 | M33: 12500 | N33: 12500 | O33: 12500 | P33: 12500 | W33: =SUM(K33:V33) | Y33: T0031 | Z33: P03-204 | AA33: C026 | AB33: P03
A34: 32 | B34: ابو بكر | C34: د/ محمد عبد الحليم محمود | D34: محمد عبد الحليم محمود | E34: 204 | F34: شارع ابو بكر الصديق 3 | G34: 46204 | H34: 46568 | J34: 28907122102999 | Q34: 14500 | R34: 14500 | W34: =SUM(K34:V34) | Y34: T0032 | Z34: P03-204 | AA34: C027 | AB34: P03
A35: 33 | B35: ابو بكر | C35: عبدالله عصام شعبان | D35: عبدالله عصام شعبان | E35: 205 | F35: شارع ابو بكر الصديق 3 | G35: 45977 | H35: 46341 | J35: N589794681 | K35: 14000 | L35: 14000 | M35: 14000 | N35: 14000 | O35: 14000 | P35: 14000 | Q35: 14000 | R35: 14000 | W35: =SUM(K35:V35) | Y35: T0033 | Z35: P03-205 | AA35: C028 | AB35: P03
A36: 34 | B36: ابو بكر | C36: شركة جي اس للمنتجات الجلدية والاكسسوار | D36: جيداء يسر محمد | E36: 206 | F36: شارع ابو بكر الصديق 3 | G36: 45901 | H36: 46264 | J36: 26306292101365 | K36: 16500 | L36: 16500 | M36: 16500 | N36: 16500 | O36: 16500 | P36: 16500 | Q36: 16500 | R36: 16500 | W36: =SUM(K36:V36) | Y36: T0034 | Z36: P03-206 | AA36: C029 | AB36: P03
A37: 35 | B37: ابو بكر | C37: د/ رامه هاشم ابو زيد | D37: رامه هاشم ابو زيد | E37: 207 | F37: شارع ابو بكر الصديق 3 | G37: 46143 | H37: 46507 | J37: P13199335 | O37: 20000 | P37: 20000 | Q37: 20000 | R37: 20000 | W37: =SUM(K37:V37) | Y37: T0035 | Z37: P03-207 | AA37: C030 | AB37: P03
A38: 36 | B38: ابو بكر | C38: شركة لينيا ارت برودكشن | D38: احمد صبري عبد العزيز | E38: 208 | F38: شارع ابو بكر الصديق 3 | G38: 45383 | H38: 46477 | I38: 337-707-162 | J38: 27310061501011 | K38: 19250 | L38: 19250 | M38: 19250 | N38: 21175 | O38: 21175 | P38: 21175 | Q38: 21175 | R38: 21175 | W38: =SUM(K38:V38) | Y38: T0036 | Z38: P03-208 | AA38: C031 | AB38: P03
A39: 37 | B39: ابو بكر | C39: حسام عبد المحسن شحات | D39: حسام عبد المحسن شحات | E39: 301 | F39: شارع ابو بكر الصديق 3 | G39: 45920 | H39: 46284 | J39: 29909152101756 | K39: 17000 | L39: 17000 | M39: 17000 | N39: 17000 | O39: 17000 | W39: =SUM(K39:V39) | Y39: T0037 | Z39: P03-301 | AA39: C032 | AB39: P03
A40: 38 | B40: ابو بكر | C40: وليد محمد عبد القادر | D40: وليد محمد عبد القادر | E40: 302 | F40: شارع ابو بكر الصديق 3 | G40: 45916 | H40: 46280 | I40: 723-549-699 | J40: 28210160103159 | K40: 17000 | L40: 17000 | M40: 17000 | N40: 17000 | O40: 17000 | P40: 17000 | Q40: 17000 | R40: 17000 | W40: =SUM(K40:V40) | Y40: T0038 | Z40: P03-302 | AA40: C033 | AB40: P03
...

Sheet ملخص المشاريع
A1: المشروع | B1: عدد الصفوف في 2026 | C1: إجمالي 2026 | D1: عدد الوحدات | E1: مؤجَّرة | F1: شاغرة | G1: نسبة الإشغال | H1: المتأخرات | I1: كود المشروع
A2: بابل | B2: =COUNTIF('2026'!B3:B75,A2) | C2: =SUMIF('2026'!B3:B75,A2,'2026'!W3:W75) | D2: 7 | E2: 2 | F2: 5 | G2: 0.28571429 | H2: 283383 | I2: P01
A3: محيي الدين | B3: =COUNTIF('2026'!B3:B75,A3) | C3: =SUMIF('2026'!B3:B75,A3,'2026'!W3:W75) | D3: 12 | E3: 10 | F3: 2 | G3: 0.83333333 | H3: 752580 | I3: P02
A4: ابو بكر | B4: =COUNTIF('2026'!B3:B75,A4) | C4: =SUMIF('2026'!B3:B75,A4,'2026'!W3:W75) | D4: 52 | E4: 35 | F4: 17 | G4: 0.67307692 | H4: 1362576 | I4: P03
A5: الاجمالي | B5: =SUM(B2:B4) | C5: =SUM(C2:C4) | D5: =SUM(D2:D4) | E5: =SUM(E2:E4) | F5: =SUM(F2:F4) | H5: =SUM(H2:H4)

Sheet المشاريع
A1: كود المشروع | B1: اسم المشروع | C1: العنوان | D1: المنطقة | E1: ملاحظات | F1: تاريخ الإضافة | G1: عدد الوحدات (محسوب) | H1: مؤجَّرة (محسوب) | I1: شاغرة (محسوب) | J1: المتأخرات (محسوب) | K1: محصَّل السنة (محسوب)
A2: P01 | B2: بابل | C2: شارع بابل الدقي 39 | G2: 7 | H2: 2 | I2: 5 | J2: 283383 | K2: 1818148
A3: P02 | B3: محيي الدين | C3: شارع محيي الدين ابو العز 30 | G3: 12 | H3: 10 | I3: 2 | J3: 752580 | K3: 3071865
A4: P03 | B4: ابو بكر | C4: شارع ابو بكر الصديق 3 | G4: 52 | H4: 35 | I4: 17 | J4: 1362576 | K4: 5449810

Sheet الوحدات
A1: كود الوحدة | B1: كود المشروع | C1: المشروع | D1: رقم / اسم الوحدة | E1: النوع | F1: الدور | G1: المساحة م² | H1: ملاحظات | I1: تاريخ الإضافة | J1: الأصول (ملخص) | K1: الحالة (محسوب) | L1: المستأجر الحالي (محسوب) | M1: العقد الحالي (محسوب) | N1: الإيجار الحالي (محسوب) | O1: شاغرة منذ (محسوب) | P1: أيام الشغور (محسوب)
A2: P01-S1 | B2: P01 | C2: بابل | D2: محل | E2: تجارية | F2: G | K2: شاغرة | O2: 01/06/2026 | P2: 130
A3: P01-S2 | B3: P01 | C3: بابل | D3: محل | E3: تجارية | F3: G | K3: شاغرة | O3: 01/05/2026 | P3: 161
A4: P01-M1-2 | B4: P01 | C4: بابل | D4: ميزان 1/2 | E4: إدارية | F4: M | K4: مؤجَّرة | L4: شركة الدقة للاستشارات الهندسية | M4: T0003 | N4: 49610 | P4: 0
A5: P01-M3 | B5: P01 | C5: بابل | D5: ميزان 3 | E5: إدارية | F5: M | K5: شاغرة | O5: 01/06/2026 | P5: 130
A6: P01-F2 | B6: P01 | C6: بابل | D6: الدور الثاني | E6: إدارية | F6: 2 | K6: مؤجَّرة | L6: شركة الدقة للاستشارات الهندسية | M6: T0005 | N6: 91960 | P6: 0
A7: P01-O42 | B7: P01 | C7: بابل | D7: مكتب 42 | E7: إدارية | F7: 4 | K7: شاغرة | O7: 20/08/2026 | P7: 50
A8: P01-O61 | B8: P01 | C8: بابل | D8: مكتب 61 | E8: إدارية | F8: 6 | K8: شاغرة | O8: 01/04/2026 | P8: 191
A9: P02-M1 | B9: P02 | C9: محيي الدين | D9: ميزان 1 | E9: إدارية | F9: M | K9: مؤجَّرة | L9: شركة مستر تايلور | M9: T0008 | N9: 46585 | P9: 0
A10: P02-M2 | B10: P02 | C10: محيي الدين | D10: ميزان 2 | E10: إدارية | F10: M | K10: تنتهي قريبًا | L10: شركة صحة سكان | M10: T0009 | N10: 25410 | P10: 0
A11: P02-202 | B11: P02 | C11: محيي الدين | D11: 202 | E11: إدارية | F11: 2 | K11: تنتهي قريبًا | L11: شركة ستاف ارابيا | M11: T0010 | N11: 46585 | P11: 0
A12: P02-301 | B12: P02 | C12: محيي الدين | D12: 301 | E12: إدارية | F12: 3 | K12: مؤجَّرة | L12: علي فرغلي علي | M12: T0011 | N12: 37000 | P12: 0
A13: P02-302 | B13: P02 | C13: محيي الدين | D13: 302 | E13: إدارية | F13: 3 | K13: مؤجَّرة | L13: دكتور شريف عزت عبد الخالق | M13: T0012 | N13: 38500 | P13: 0
A14: P02-303 | B14: P02 | C14: محيي الدين | D14: 303 | E14: إدارية | F14: 3 | K14: مؤجَّرة | L14: شركة ايجل اي ميدل ايست | M14: T0013 | N14: 49450 | P14: 0
A15: P02-304 | B15: P02 | C15: محيي الدين | D15: 304 | E15: إدارية | F15: 3 | K15: مؤجَّرة | L15: شركة ايجل اي ميدل ايست | M15: T0014 | N15: 27830 | P15: 0
A16: P02-401 | B16: P02 | C16: محيي الدين | D16: 401 | E16: إدارية | F16: 4 | K16: مؤجَّرة | L16: دكتور ياسر خالد بادي محمد | M16: T0015 | N16: 37665 | P16: 0
A17: P02-404 | B17: P02 | C17: محيي الدين | D17: 404 | E17: إدارية | F17: 4 | K17: تنتهي قريبًا | L17: دكتور عمرو هشام محمد | M17: T0016 | N17: 30250 | P17: 0
A18: P02-502 | B18: P02 | C18: محيي الدين | D18: 502 | E18: إدارية | F18: 5 | K18: شاغرة | O18: 01/09/2026 | P18: 38
A19: P02-503 | B19: P02 | C19: محيي الدين | D19: 503 | E19: إدارية | F19: 5 | K19: شاغرة | O19: 01/10/2026 | P19: 8
A20: P02-504 | B20: P02 | C20: محيي الدين | D20: 504 | E20: إدارية | F20: 5 | K20: تنتهي قريبًا | L20: حمدي جمال حمدي | M20: T0019 | N20: 25410 | P20: 0
A21: P03-M1 | B21: P03 | C21: ابو بكر | D21: ميزان 1 | E21: إدارية | F21: M | K21: مؤجَّرة | L21: شركة موريشي للاستيراد والتصدير | M21: T0020 | N21: 44770 | P21: 0
A22: P03-M2 | B22: P03 | C22: ابو بكر | D22: ميزان 2 | E22: إدارية | F22: M | K22: مؤجَّرة | L22: شركة تسفع لتطوير المهارات | M22: T0021 | N22: 44770 | P22: 0
A23: P03-102 | B23: P03 | C23: ابو بكر | D23: 102 | E23: إدارية | F23: 1 | K23: مؤجَّرة | L23: احمد هاشم احمد | M23: T0022 | N23: 20000 | P23: 0
A24: P03-103 | B24: P03 | C24: ابو بكر | D24: 103 | E24: إدارية | F24: 1 | K24: تنتهي قريبًا | L24: عبد الرحمن هلال احمد | M24: T0023 | N24: 7000 | P24: 0
A25: P03-104 | B25: P03 | C25: ابو بكر | D25: 104 | E25: إدارية | F25: 1 | K25: مؤجَّرة | L25: وليد عبد الرحمن عبد الكريم | M25: T0024 | N25: 15000 | P25: 0
A26: P03-105 | B26: P03 | C26: ابو بكر | D26: 105 | E26: إدارية | F26: 1 | K26: مؤجَّرة | L26: احمد هاشم احمد | M26: T0025 | N26: 15000 | P26: 0
A27: P03-106 | B27: P03 | C27: ابو بكر | D27: 106 | E27: إدارية | F27: 1 | K27: تنتهي قريبًا | L27: محمد هلال احمد | M27: T0026 | N27: 7000 | P27: 0
A28: P03-107 | B28: P03 | C28: ابو بكر | D28: 107 | E28: إدارية | F28: 1 | K28: مؤجَّرة | L28: محمد هلال احمد | M28: T0027 | N28: 8000 | P28: 0
A29: P03-108 | B29: P03 | C29: ابو بكر | D29: 108 | E29: إدارية | F29: 1 | K29: مؤجَّرة | L29: محمد هلال احمد | M29: T0028 | N29: 8000 | P29: 0
A30: P03-201 | B30: P03 | C30: ابو بكر | D30: 201 | E30: إدارية | F30: 2 | K30: شاغرة | O30: 01/06/2026 | P30: 130
A31: P03-202 | B31: P03 | C31: ابو بكر | D31: 202 | E31: إدارية | F31: 2 | K31: شاغرة | O31: 01/09/2026 | P31: 38
A32: P03-204 | B32: P03 | C32: ابو بكر | D32: 204 | E32: إدارية | F32: 2 | K32: مؤجَّرة | L32: د/ محمد عبد الحليم محمود | M32: T0032 | N32: 14500 | P32: 0
A33: P03-205 | B33: P03 | C33: ابو بكر | D33: 205 | E33: إدارية | F33: 2 | K33: تنتهي قريبًا | L33: عبدالله عصام شعبان | M33: T0033 | N33: 14000 | P33: 0
A34: P03-206 | B34: P03 | C34: ابو بكر | D34: 206 | E34: إدارية | F34: 2 | K34: شاغرة | O34: 31/08/2026 | P34: 39
A35: P03-207 | B35: P03 | C35: ابو بكر | D35: 207 | E35: إدارية | F35: 2 | K35: مؤجَّرة | L35: د/ رامه هاشم ابو زيد | M35: T0035 | N35: 20000 | P35: 0
A36: P03-208 | B36: P03 | C36: ابو بكر | D36: 208 | E36: إدارية | F36: 2 | K36: مؤجَّرة | L36: شركة لينيا ارت برودكشن | M36: T0036 | N36: 21175 | P36: 0
A37: P03-301 | B37: P03 | C37: ابو بكر | D37: 301 | E37: إدارية | F37: 3 | K37: شاغرة | O37: 20/09/2026 | P37: 19
A38: P03-302 | B38: P03 | C38: ابو بكر | D38: 302 | E38: إدارية | F38: 3 | K38: شاغرة | O38: 16/09/2026 | P38: 23
A39: P03-303 | B39: P03 | C39: ابو بكر | D39: 303 | E39: إدارية | F39: 3 | K39: مؤجَّرة | L39: احمد هاشم احمد | M39: T0039 | N39: 19000 | P39: 0
A40: P03-304 | B40: P03 | C40: ابو بكر | D40: 304 | E40: إدارية | F40: 3 | K40: مؤجَّرة | L40: سارة سيد احمد | M40: T0041 | N40: 14000 | P40: 0
...

Sheet أصول الوحدات
A1: كود الوحدة | B1: الأصل | C1: موجود | D1: التفاصيل

Sheet العملاء
A1: كود العميل | B1: الاسم | C1: النوع | D1: الممثل القانوني | E1: الرقم القومي / الباسبور | F1: تسجيل ضريبي | G1: التليفون | H1: تليفون آخر | I1: البريد الإلكتروني | J1: العنوان | K1: ملاحظات | L1: تاريخ الإضافة | M1: عدد العقود (محسوب) | N1: عقود سارية (محسوب) | O1: المتأخرات (محسوب) | P1: إجمالي المسدَّد (محسوب)
A2: C001 | B2: حسام حسن سنوسي | C2: فرد | D2: يوسف حسن سنوسي | E2: 29202162300777 | M2: 1 | N2: 0 | O2: 0 | P2: 63525
A3: C002 | B3: صالون ايه ام Salon A M | C3: شركة | D3: محمد ابراهيم موسى | E3: 29206013100132 | M3: 1 | N3: 0 | O3: 0 | P3: 122000
A4: C003 | B4: شركة الدقة للاستشارات الهندسية | C4: شركة | D4: محمد احمد فراج | E4: 28803262100597 | F4: 726-387-908 | M4: 2 | N4: 2 | O4: 283383 | P4: 1094793
A5: C004 | B5: شركة العنوان للانتاج الفني | C5: شركة | D5: نسرين احمد عثمان | E5: P10629999 | M5: 1 | N5: 0 | O5: 0 | P5: 209000
A6: C005 | B6: شركة ديل اند بيك للتجارة الالكترونية | C6: شركة | D6: وليد محمود مصطفى | E6: 28407140102651 | F6: 557-627-516 | M6: 1 | N6: 0 | O6: 0 | P6: 255840
A7: C006 | B7: مصطفى عثمان ابراهيم | C7: فرد | E7: 27004050101531 | M7: 1 | N7: 0 | O7: 0 | P7: 72990
A8: C007 | B8: شركة مستر تايلور | C8: شركة | D8: احمد رشد قاسم | E8: 27307022102338 | F8: 721-692-965 | M8: 1 | N8: 1 | O8: 93170 | P8: 343035
A9: C008 | B9: شركة صحة سكان | C9: شركة | D9: اشرف صلاح محمد | E9: 25510030100193 | F9: 421-187-875 | M9: 1 | N9: 1 | O9: 50820 | P9: 203280
A10: C009 | B10: شركة ستاف ارابيا | C10: شركة | D10: اياد صبحي حافظ | E10: N011661697 | F10: 567-354-873 | M10: 1 | N10: 1 | O10: 93170 | P10: 372680
A11: C010 | B11: علي فرغلي علي | C11: فرد | E11: 29705050200631 | M11: 1 | N11: 1 | O11: 74000 | P11: 239960
A12: C011 | B12: دكتور شريف عزت عبد الخالق | C12: فرد | E12: 26211150101815 | M12: 1 | N12: 1 | O12: 78000 | P12: 293000
A13: C012 | B13: شركة ايجل اي ميدل ايست | C13: شركة | D13: اسلام محمد عبد الفتاح | E13: 28910220100539 | F13: 730-874-532 | M13: 2 | N13: 2 | O13: 154560 | P13: 557910
A14: C013 | B14: دكتور ياسر خالد بادي محمد | C14: فرد | D14: ياسر خالد بادي محمد | E14: 29010208800714 | M14: 1 | N14: 1 | O14: 76970 | P14: 299680
A15: C014 | B15: دكتور عمرو هشام محمد | C15: فرد | D15: عمرو هشام محمد | E15: 29009011320232 | M15: 1 | N15: 1 | O15: 60500 | P15: 242000
A16: C015 | B16: د/ احمد محمد حسن - د/ دينا محمد سعيد | C16: فرد | E16: 27404220102918 | M16: 1 | N16: 0 | O16: 0 | P16: 152480
A17: C016 | B17: د/ ياسمين جمال - د/ محمد خطاب | C17: فرد | D17: ياسمين محمد جمال الدين - محمد حمدي محمد | E17: 28607270103607 | M17: 1 | N17: 0 | O17: 20570 | P17: 164560
A18: C017 | B18: حمدي جمال حمدي | C18: فرد | E18: 30109182600357 | M18: 1 | N18: 1 | O18: 50820 | P18: 203280
A19: C018 | B19: شركة موريشي للاستيراد والتصدير | C19: شركة | D19: محمد مصطفى محمد | E19: 28206128800771 | F19: 578-907-399 | M19: 1 | N19: 1 | O19: 89540 | P19: 329670
A20: C019 | B20: شركة تسفع لتطوير المهارات | C20: شركة | D20: محمد مصطفى محمد | E20: 28206128800771 | F20: 765-044-404 | M20: 1 | N20: 1 | O20: 89540 | P20: 329670
A21: C020 | B21: احمد هاشم احمد | C21: فرد | E21: P12786398 | M21: 3 | N21: 3 | O21: 122000 | P21: 375000
A22: C021 | B22: عبد الرحمن هلال احمد | C22: فرد | E22: 29108131301515 | M22: 1 | N22: 1 | O22: 14000 | P22: 56000
A23: C022 | B23: وليد عبد الرحمن عبد الكريم | C23: فرد | E23: X853069 | M23: 1 | N23: 1 | O23: 30000 | P23: 108000
A24: C023 | B24: محمد هلال احمد | C24: فرد | E24: 28408191301751 | M24: 4 | N24: 4 | O24: 72000 | P24: 256000
A25: C024 | B25: ارابيك في اي بي | C25: فرد | D25: ليلى جمال شعبان | E25: 29409202103248 | M25: 1 | N25: 0 | O25: 0 | P25: 57475
A26: C025 | B26: د/ احمد وجدي عبد القادر | C26: فرد | D26: احمد وجدي عبد القادر | E26: 28509092104431 | M26: 1 | N26: 0 | O26: 0 | P26: 132000
A27: C026 | B27: د/ مصطفى مجدي عوض | C27: فرد | D27: مصطفى مجدي عوض | E27: 28910178800274 | M27: 1 | N27: 0 | O27: 0 | P27: 75000
A28: C027 | B28: د/ محمد عبد الحليم محمود | C28: فرد | D28: محمد عبد الحليم محمود | E28: 28907122102999 | M28: 1 | N28: 1 | O28: 29000 | P28: 29000
A29: C028 | B29: عبدالله عصام شعبان | C29: فرد | E29: N589794681 | M29: 1 | N29: 1 | O29: 28000 | P29: 112000
A30: C029 | B30: شركة جي اس للمنتجات الجلدية والاكسسوار | C30: شركة | D30: جيداء يسر محمد | E30: 26306292101365 | M30: 1 | N30: 0 | O30: 0 | P30: 132000
A31: C030 | B31: د/ رامه هاشم ابو زيد | C31: فرد | D31: رامه هاشم ابو زيد | E31: P13199335 | M31: 1 | N31: 1 | O31: 40000 | P31: 80000
A32: C031 | B32: شركة لينيا ارت برودكشن | C32: شركة | D32: احمد صبري عبد العزيز | E32: 27310061501011 | F32: 337-707-162 | M32: 1 | N32: 1 | O32: 42350 | P32: 163625
A33: C032 | B33: حسام عبد المحسن شحات | C33: فرد | E33: 29909152101756 | M33: 1 | N33: 0 | O33: 61767 | P33: 85000
A34: C033 | B34: وليد محمد عبد القادر | C34: فرد | E34: 28210160103159 | F34: 723-549-699 | M34: 1 | N34: 0 | O34: 8500 | P34: 136000
A35: C034 | B35: خالد مصطفى الطيب | C35: فرد | E35: B00021465 | M35: 1 | N35: 0 | O35: 2702 | P35: 7565
A36: C035 | B36: سارة سيد احمد | C36: فرد | E36: P08991266 | M36: 1 | N36: 1 | O36: 28000 | P36: 14000
A37: C036 | B37: شركة سي سي بي ري للاعتماد والتفتيش الزراعي | C37: شركة | D37: ايهاب احمد عبد الرحمن | E37: 27901280101094 | F37: 640-971-180 | M37: 1 | N37: 1 | O37: 23000 | P37: 92000
A38: C037 | B38: وليد مصطفى احمد | C38: فرد | E38: 28002058800153 | M38: 1 | N38: 1 | O38: 22390 | P38: 89560
A39: C038 | B39: د/ ولاء محمد سيد جاد | C39: فرد | D39: ولاء محمد جاد | E39: 29304288800241 | M39: 1 | N39: 1 | O39: 24200 | P39: 96800
A40: C039 | B40: مبادرات وزارة الشباب والرياضة | C40: شركة | D40: امني سعد سيد محمد | E40: 28101192201744 | F40: 631-230-068 | M40: 1 | N40: 1 | O40: 24200 | P40: 91300
...

Sheet العقود
A1: كود العقد | B1: كود الوحدة | C1: كود العميل | D1: المشروع | E1: الوحدة | F1: العميل | G1: بداية العقد | H1: نهاية العقد | I1: الإيجار الشهري (السنة الأولى) | J1: الزيادة السنوية % | K1: إيجار كل سنة (يدوي) | L1: التأمين | M1: حالة التأمين | N1: يوم الاستحقاق | O1: العقد السابق | P1: ملاحظات | Q1: ترتيب الورقة | R1: تاريخ الإضافة | S1: الحالة (محسوب) | T1: الإيجار الحالي (محسوب) | U1: المسدَّد (محسوب) | V1: المتأخرات (محسوب) | W1: جدول السنوات (محسوب)
A2: T0001 | B2: P01-S1 | C2: C001 | D2: بابل | E2: محل | F2: حسام حسن سنوسي | G2: 45078 | H2: 46173 | I2: 12705 | J2: 0 | K2: 3:12705 | L2: 0 | M2: بدون تأمين | N2: 1 | Q2: 1 | S2: منتهٍ | T2: 12705 | U2: 63525 | V2: 0 | W2: س1 01/06/2023–31/05/2024: 12,705 | س2 01/06/2024–31/05/2025: 12,705 | س3 01/06/2025–31/05/2026: 12,705
A3: T0002 | B3: P01-S2 | C3: C002 | D3: بابل | E3: محل | F3: صالون ايه ام Salon A M | G3: 45778 | H3: 46142 | I3: 30500 | J3: 0 | L3: 0 | M3: بدون تأمين | N3: 1 | Q3: 2 | S3: منتهٍ | T3: 30500 | U3: 122000 | V3: 0 | W3: س1 01/05/2025–30/04/2026: 30,500
A4: T0003 | B4: P01-M1-2 | C4: C003 | D4: بابل | E4: ميزان 1/2 | F4: شركة الدقة للاستشارات الهندسية | G4: 45432 | H4: 46526 | I4: 41000 | J4: 10 | K4: 2:45100; 3:49610 | L4: 0 | M4: بدون تأمين | N4: 1 | Q4: 3 | S4: ساري | T4: 49610 | U4: 375833 | V4: 99463 | W4: س1 20/05/2024–19/05/2025: 41,000 | س2 20/05/2025–19/05/2026: 45,100 | س3 20/05/2026–19/05/2027: 49,610
A5: T0004 | B5: P01-M3 | C5: C004 | D5: بابل | E5: ميزان 3 | F5: شركة العنوان للانتاج الفني | G5: 45444 | H5: 46173 | I5: 41800 | J5: 0 | K5: 2:41800 | L5: 0 | M5: بدون تأمين | N5: 1 | Q5: 4 | S5: منتهٍ | T5: 41800 | U5: 209000 | V5: 0 | W5: س1 01/06/2024–31/05/2025: 41,800 | س2 01/06/2025–31/05/2026: 41,800
A6: T0005 | B6: P01-F2 | C6: C003 | D6: بابل | E6: الدور الثاني | F6: شركة الدقة للاستشارات الهندسية | G6: 45352 | H6: 46446 | I6: 76000 | J6: 10 | K6: 2:83600; 3:91960 | L6: 0 | M6: بدون تأمين | N6: 1 | Q6: 5 | S6: ساري | T6: 91960 | U6: 718960 | V6: 183920 | W6: س1 01/03/2024–28/02/2025: 76,000 | س2 01/03/2025–28/02/2026: 83,600 | س3 01/03/2026–28/02/2027: 91,960
A7: T0006 | B7: P01-O42 | C7: C005 | D7: بابل | E7: مكتب 42 | F7: شركة ديل اند بيك للتجارة الالكترونية | G7: 45158 | H7: 46253 | I7: 30250 | J7: 0 | K7: 3:30250 | L7: 0 | M7: بدون تأمين | N7: 1 | Q7: 6 | S7: منتهٍ | T7: 30250 | U7: 255840 | V7: 0 | W7: س1 20/08/2023–19/08/2024: 30,250 | س2 20/08/2024–19/08/2025: 30,250 | س3 20/08/2025–19/08/2026: 30,250
A8: T0007 | B8: P01-O61 | C8: C006 | D8: بابل | E8: مكتب 61 | F8: مصطفى عثمان ابراهيم | G8: 45017 | H8: 46112 | I8: 24330 | J8: 0 | K8: 3:24330 | L8: 0 | M8: بدون تأمين | N8: 1 | Q8: 7 | S8: منتهٍ | T8: 24330 | U8: 72990 | V8: 0 | W8: س1 01/04/2023–31/03/2024: 24,330 | س2 01/04/2024–31/03/2025: 24,330 | س3 01/04/2025–31/03/2026: 24,330
A9: T0008 | B9: P02-M1 | C9: C007 | D9: محيي الدين | E9: ميزان 1 | F9: شركة مستر تايلور | G9: 45139 | H9: 46965 | I9: 35000 | J9: 10 | K9: 3:42350; 4:46585 | L9: 0 | M9: بدون تأمين | N9: 1 | Q9: 8 | S9: ساري | T9: 46585 | U9: 343035 | V9: 93170 | W9: س1 01/08/2023–31/07/2024: 35,000 | س2 01/08/2024–31/07/2025: 38,500 | س3 01/08/2025–31/07/2026: 42,350 | س4 01/08/2026–31/07/2027: 46,585 | س5 01/08/2027–31/07/2028: 51,244
A10: T0009 | B10: P02-M2 | C10: C008 | D10: محيي الدين | E10: ميزان 2 | F10: شركة صحة سكان | G10: 45242 | H10: 46337 | I10: 25410 | J10: 0 | K10: 3:25410 | L10: 0 | M10: بدون تأمين | N10: 1 | Q10: 9 | S10: ساري | T10: 25410 | U10: 203280 | V10: 50820 | W10: س1 12/11/2023–11/11/2024: 25,410 | س2 12/11/2024–11/11/2025: 25,410 | س3 12/11/2025–11/11/2026: 25,410
A11: T0010 | B11: P02-202 | C11: C009 | D11: محيي الدين | E11: 202 | F11: شركة ستاف ارابيا | G11: 45231 | H11: 46326 | I11: 46585 | J11: 0 | K11: 3:46585 | L11: 0 | M11: بدون تأمين | N11: 1 | Q11: 10 | S11: ساري | T11: 46585 | U11: 372680 | V11: 93170 | W11: س1 01/11/2023–31/10/2024: 46,585 | س2 01/11/2024–31/10/2025: 46,585 | س3 01/11/2025–31/10/2026: 46,585
A12: T0011 | B12: P02-301 | C12: C010 | D12: محيي الدين | E12: 301 | F12: علي فرغلي علي | G12: 46143 | H12: 46507 | I12: 37000 | J12: 0 | L12: 0 | M12: بدون تأمين | N12: 1 | Q12: 11 | S12: ساري | T12: 37000 | U12: 239960 | V12: 74000 | W12: س1 01/05/2026–30/04/2027: 37,000
A13: T0012 | B13: P02-302 | C13: C011 | D13: محيي الدين | E13: 302 | F13: دكتور شريف عزت عبد الخالق | G13: 46143 | H13: 46507 | I13: 38500 | J13: 0 | L13: 0 | M13: بدون تأمين | N13: 1 | Q13: 12 | S13: ساري | T13: 38500 | U13: 293000 | V13: 78000 | W13: س1 01/05/2026–30/04/2027: 38,500
A14: T0013 | B14: P02-303 | C14: C012 | D14: محيي الدين | E14: 303 | F14: شركة ايجل اي ميدل ايست | G14: 45870 | H14: 46965 | I14: 43000 | J14: 15 | K14: 2:49450 | L14: 0 | M14: بدون تأمين | N14: 1 | Q14: 13 | S14: ساري | T14: 49450 | U14: 350450 | V14: 98900 | W14: س1 01/08/2025–31/07/2026: 43,000 | س2 01/08/2026–31/07/2027: 49,450 | س3 01/08/2027–31/07/2028: 56,867
A15: T0014 | B15: P02-304 | C15: C012 | D15: محيي الدين | E15: 304 | F15: شركة ايجل اي ميدل ايست | G15: 45474 | H15: 46568 | I15: 23000 | J15: 10 | K15: 2:25300; 3:27830 | L15: 0 | M15: بدون تأمين | N15: 1 | Q15: 14 | S15: ساري | T15: 27830 | U15: 207460 | V15: 55660 | W15: س1 01/07/2024–30/06/2025: 23,000 | س2 01/07/2025–30/06/2026: 25,300 | س3 01/07/2026–30/06/2027: 27,830
A16: T0015 | B16: P02-401 | C16: C013 | D16: محيي الدين | E16: 401 | F16: دكتور ياسر خالد بادي محمد | G16: 45668 | H16: 46397 | I16: 37665 | J16: 0 | K16: 2:37665 | L16: 0 | M16: بدون تأمين | N16: 1 | Q16: 15 | S16: ساري | T16: 37665 | U16: 299680 | V16: 76970 | W16: س1 11/01/2025–10/01/2026: 37,665 | س2 11/01/2026–10/01/2027: 37,665
A17: T0016 | B17: P02-404 | C17: C014 | D17: محيي الدين | E17: 404 | F17: دكتور عمرو هشام محمد | G17: 45292 | H17: 46387 | I17: 30250 | J17: 0 | K17: 3:30250 | L17: 0 | M17: بدون تأمين | N17: 1 | Q17: 16 | S17: ساري | T17: 30250 | U17: 242000 | V17: 60500 | W17: س1 01/01/2024–31/12/2024: 30,250 | س2 01/01/2025–31/12/2025: 30,250 | س3 01/01/2026–31/12/2026: 30,250
A18: T0017 | B18: P02-502 | C18: C015 | D18: محيي الدين | E18: 502 | F18: د/ احمد محمد حسن - د/ دينا محمد سعيد | G18: 45170 | H18: 46265 | I18: 19060 | J18: 0 | K18: 3:19060 | L18: 0 | M18: بدون تأمين | N18: 1 | Q18: 17 | S18: منتهٍ | T18: 19060 | U18: 152480 | V18: 0 | W18: س1 01/09/2023–31/08/2024: 19,060 | س2 01/09/2024–31/08/2025: 19,060 | س3 01/09/2025–31/08/2026: 19,060
A19: T0018 | B19: P02-503 | C19: C016 | D19: محيي الدين | E19: 503 | F19: د/ ياسمين جمال - د/ محمد خطاب | G19: 45200 | H19: 46295 | I19: 20570 | J19: 0 | K19: 3:20570 | L19: 0 | M19: بدون تأمين | N19: 1 | Q19: 18 | S19: منتهٍ | T19: 20570 | U19: 164560 | V19: 20570 | W19: س1 01/10/2023–30/09/2024: 20,570 | س2 01/10/2024–30/09/2025: 20,570 | س3 01/10/2025–30/09/2026: 20,570
A20: T0019 | B20: P02-504 | C20: C017 | D20: محيي الدين | E20: 504 | F20: حمدي جمال حمدي | G20: 45231 | H20: 46326 | I20: 25410 | J20: 0 | K20: 3:25410 | L20: 0 | M20: بدون تأمين | N20: 1 | Q20: 19 | S20: ساري | T20: 25410 | U20: 203280 | V20: 50820 | W20: س1 01/11/2023–31/10/2024: 25,410 | س2 01/11/2024–31/10/2025: 25,410 | س3 01/11/2025–31/10/2026: 25,410
A21: T0020 | B21: P03-M1 | C21: C018 | D21: ابو بكر | E21: ميزان 1 | F21: شركة موريشي للاستيراد والتصدير | G21: 45505 | H21: 46599 | I21: 37000 | J21: 10 | K21: 2:40700; 3:44770 | L21: 0 | M21: بدون تأمين | N21: 1 | Q21: 20 | S21: ساري | T21: 44770 | U21: 329670 | V21: 89540 | W21: س1 01/08/2024–31/07/2025: 37,000 | س2 01/08/2025–31/07/2026: 40,700 | س3 01/08/2026–31/07/2027: 44,770
A22: T0021 | B22: P03-M2 | C22: C019 | D22: ابو بكر | E22: ميزان 2 | F22: شركة تسفع لتطوير المهارات | G22: 45505 | H22: 46599 | I22: 37000 | J22: 10 | K22: 2:40700; 3:44770 | L22: 0 | M22: بدون تأمين | N22: 1 | Q22: 21 | S22: ساري | T22: 44770 | U22: 329670 | V22: 89540 | W22: س1 01/08/2024–31/07/2025: 37,000 | س2 01/08/2025–31/07/2026: 40,700 | س3 01/08/2026–31/07/2027: 44,770
A23: T0022 | B23: P03-102 | C23: C020 | D23: ابو بكر | E23: 102 | F23: احمد هاشم احمد | G23: 46204 | H23: 46568 | I23: 20000 | J23: 0 | L23: 0 | M23: بدون تأمين | N23: 1 | Q23: 22 | S23: ساري | T23: 20000 | U23: 145000 | V23: 40000 | W23: س1 01/07/2026–30/06/2027: 20,000
A24: T0023 | B24: P03-103 | C24: C021 | D24: ابو بكر | E24: 103 | F24: عبد الرحمن هلال احمد | G24: 45992 | H24: 46356 | I24: 7000 | J24: 0 | L24: 0 | M24: بدون تأمين | N24: 1 | Q24: 23 | S24: ساري | T24: 7000 | U24: 56000 | V24: 14000 | W24: س1 01/12/2025–30/11/2026: 7,000
A25: T0024 | B25: P03-104 | C25: C022 | D25: ابو بكر | E25: 104 | F25: وليد عبد الرحمن عبد الكريم | G25: 46204 | H25: 46568 | I25: 15000 | J25: 0 | L25: 0 | M25: بدون تأمين | N25: 1 | Q25: 24 | S25: ساري | T25: 15000 | U25: 108000 | V25: 30000 | W25: س1 01/07/2026–30/06/2027: 15,000
A26: T0025 | B26: P03-105 | C26: C020 | D26: ابو بكر | E26: 105 | F26: احمد هاشم احمد | G26: 46204 | H26: 46568 | I26: 15000 | J26: 0 | L26: 0 | M26: بدون تأمين | N26: 1 | Q26: 25 | S26: ساري | T26: 15000 | U26: 97000 | V26: 44000 | W26: س1 01/07/2026–30/06/2027: 15,000
A27: T0026 | B27: P03-106 | C27: C023 | D27: ابو بكر | E27: 106 | F27: محمد هلال احمد | G27: 45992 | H27: 46356 | I27: 7000 | J27: 0 | L27: 0 | M27: بدون تأمين | N27: 1 | Q27: 26 | S27: ساري | T27: 7000 | U27: 56000 | V27: 14000 | W27: س1 01/12/2025–30/11/2026: 7,000
A28: T0027 | B28: P03-107 | C28: C023 | D28: ابو بكر | E28: 107 | F28: محمد هلال احمد | G28: 46204 | H28: 46568 | I28: 8000 | J28: 0 | L28: 0 | M28: بدون تأمين | N28: 1 | Q28: 27 | S28: ساري | T28: 8000 | U28: 54000 | V28: 16000 | W28: س1 01/07/2026–30/06/2027: 8,000
A29: T0028 | B29: P03-108 | C29: C023 | D29: ابو بكر | E29: 108 | F29: محمد هلال احمد | G29: 46204 | H29: 46568 | I29: 8000 | J29: 0 | L29: 0 | M29: بدون تأمين | N29: 1 | Q29: 28 | S29: ساري | T29: 8000 | U29: 54000 | V29: 16000 | W29: س1 01/07/2026–30/06/2027: 8,000
A30: T0029 | B30: P03-201 | C30: C024 | D30: ابو بكر | E30: 201 | F30: ارابيك في اي بي | G30: 45078 | H30: 46173 | I30: 11495 | J30: 0 | K30: 3:11495 | L30: 0 | M30: بدون تأمين | N30: 1 | Q30: 29 | S30: منتهٍ | T30: 11495 | U30: 57475 | V30: 0 | W30: س1 01/06/2023–31/05/2024: 11,495 | س2 01/06/2024–31/05/2025: 11,495 | س3 01/06/2025–31/05/2026: 11,495
A31: T0030 | B31: P03-202 | C31: C025 | D31: ابو بكر | E31: 202 | F31: د/ احمد وجدي عبد القادر | G31: 45901 | H31: 46265 | I31: 16500 | J31: 0 | L31: 0 | M31: بدون تأمين | N31: 1 | Q31: 30 | S31: منتهٍ | T31: 16500 | U31: 132000 | V31: 0 | W31: س1 01/09/2025–31/08/2026: 16,500
A32: T0031 | B32: P03-204 | C32: C026 | D32: ابو بكر | E32: 204 | F32: د/ مصطفى مجدي عوض | G32: 45839 | H32: 46203 | I32: 12500 | J32: 0 | L32: 0 | M32: بدون تأمين | N32: 1 | Q32: 31 | S32: منتهٍ (أُجِّرت بعده) | T32: 12500 | U32: 75000 | V32: 0 | W32: س1 01/07/2025–30/06/2026: 12,500
A33: T0032 | B33: P03-204 | C33: C027 | D33: ابو بكر | E33: 204 | F33: د/ محمد عبد الحليم محمود | G33: 46204 | H33: 46568 | I33: 14500 | J33: 0 | L33: 0 | M33: بدون تأمين | N33: 1 | Q33: 32 | S33: ساري | T33: 14500 | U33: 29000 | V33: 29000 | W33: س1 01/07/2026–30/06/2027: 14,500
A34: T0033 | B34: P03-205 | C34: C028 | D34: ابو بكر | E34: 205 | F34: عبدالله عصام شعبان | G34: 45977 | H34: 46341 | I34: 14000 | J34: 0 | L34: 0 | M34: بدون تأمين | N34: 1 | Q34: 33 | S34: ساري | T34: 14000 | U34: 112000 | V34: 28000 | W34: س1 16/11/2025–15/11/2026: 14,000
A35: T0034 | B35: P03-206 | C35: C029 | D35: ابو بكر | E35: 206 | F35: شركة جي اس للمنتجات الجلدية والاكسسوار | G35: 45901 | H35: 46264 | I35: 16500 | J35: 0 | L35: 0 | M35: بدون تأمين | N35: 1 | Q35: 34 | S35: منتهٍ | T35: 16500 | U35: 132000 | V35: 0 | W35: س1 01/09/2025–30/08/2026: 16,500
A36: T0035 | B36: P03-207 | C36: C030 | D36: ابو بكر | E36: 207 | F36: د/ رامه هاشم ابو زيد | G36: 46143 | H36: 46507 | I36: 20000 | J36: 0 | L36: 0 | M36: بدون تأمين | N36: 1 | Q36: 35 | S36: ساري | T36: 20000 | U36: 80000 | V36: 40000 | W36: س1 01/05/2026–30/04/2027: 20,000
A37: T0036 | B37: P03-208 | C37: C031 | D37: ابو بكر | E37: 208 | F37: شركة لينيا ارت برودكشن | G37: 45383 | H37: 46477 | I37: 17500 | J37: 10 | K37: 2:19250; 3:21175 | L37: 0 | M37: بدون تأمين | N37: 1 | Q37: 36 | S37: ساري | T37: 21175 | U37: 163625 | V37: 42350 | W37: س1 01/04/2024–31/03/2025: 17,500 | س2 01/04/2025–31/03/2026: 19,250 | س3 01/04/2026–31/03/2027: 21,175
A38: T0037 | B38: P03-301 | C38: C032 | D38: ابو بكر | E38: 301 | F38: حسام عبد المحسن شحات | G38: 45920 | H38: 46284 | I38: 17000 | J38: 0 | L38: 0 | M38: بدون تأمين | N38: 1 | Q38: 37 | S38: منتهٍ | T38: 17000 | U38: 85000 | V38: 61767 | W38: س1 20/09/2025–19/09/2026: 17,000
A39: T0038 | B39: P03-302 | C39: C033 | D39: ابو بكر | E39: 302 | F39: وليد محمد عبد القادر | G39: 45916 | H39: 46280 | I39: 17000 | J39: 0 | L39: 0 | M39: بدون تأمين | N39: 1 | Q39: 38 | S39: منتهٍ | T39: 17000 | U39: 136000 | V39: 8500 | W39: س1 16/09/2025–15/09/2026: 17,000
A40: T0039 | B40: P03-303 | C40: C020 | D40: ابو بكر | E40: 303 | F40: احمد هاشم احمد | G40: 46054 | H40: 46418 | I40: 19000 | J40: 0 | L40: 0 | M40: بدون تأمين | N40: 1 | Q40: 39 | S40: ساري | T40: 19000 | U40: 133000 | V40: 38000 | W40: س1 01/02/2026–31/01/2027: 19,000
...

Sheet المدفوعات
A1: رقم الفاتورة | B1: كود العقد | C1: العميل | D1: الوحدة | E1: الشهر | F1: المبلغ | G1: تاريخ السداد | H1: طريقة السداد | I1: مرجع / إيصال | J1: ملاحظات | K1: المصدر | L1: تاريخ التسجيل
A2: INV-2026-0001 | B2: T0001 | C2: حسام حسن سنوسي | D2: محل | E2: 2026-01 | F2: 12705 | H2: غير محدد | K2: الإكسيل | L2: 46304
A3: INV-2026-0006 | B3: T0002 | C3: صالون ايه ام Salon A M | D3: محل | E3: 2026-01 | F3: 30500 | H3: غير محدد | K3: الإكسيل | L3: 46304
A4: INV-2026-0010 | B4: T0003 | C4: شركة الدقة للاستشارات الهندسية | D4: ميزان 1/2 | E4: 2026-01 | F4: 45100 | H4: غير محدد | K4: الإكسيل | L4: 46304
A5: INV-2026-0018 | B5: T0004 | C5: شركة العنوان للانتاج الفني | D5: ميزان 3 | E5: 2026-01 | F5: 41800 | H5: غير محدد | K5: الإكسيل | L5: 46304
A6: INV-2026-0023 | B6: T0005 | C6: شركة الدقة للاستشارات الهندسية | D6: الدور الثاني | E6: 2026-01 | F6: 83600 | H6: غير محدد | K6: الإكسيل | L6: 46304
A7: INV-2026-0031 | B7: T0006 | C7: شركة ديل اند بيك للتجارة الالكترونية | D7: مكتب 42 | E7: 2026-01 | F7: 30250 | H7: غير محدد | K7: الإكسيل | L7: 46304
A8: INV-2026-0039 | B8: T0007 | C8: مصطفى عثمان ابراهيم | D8: مكتب 61 | E8: 2026-01 | F8: 24330 | H8: غير محدد | K8: الإكسيل | L8: 46304
A9: INV-2026-0042 | B9: T0008 | C9: شركة مستر تايلور | D9: ميزان 1 | E9: 2026-01 | F9: 42350 | H9: غير محدد | K9: الإكسيل | L9: 46304
A10: INV-2026-0050 | B10: T0009 | C10: شركة صحة سكان | D10: ميزان 2 | E10: 2026-01 | F10: 25410 | H10: غير محدد | K10: الإكسيل | L10: 46304
A11: INV-2026-0058 | B11: T0010 | C11: شركة ستاف ارابيا | D11: 202 | E11: 2026-01 | F11: 46585 | H11: غير محدد | K11: الإكسيل | L11: 46304
A12: INV-2026-0066 | B12: T0011 | C12: علي فرغلي علي | D12: 301 | E12: 2026-01 | F12: 22990 | H12: غير محدد | K12: الإكسيل | L12: 46304
A13: INV-2026-0074 | B13: T0012 | C13: دكتور شريف عزت عبد الخالق | D13: 302 | E13: 2026-01 | F13: 35000 | H13: غير محدد | K13: الإكسيل | L13: 46304
... A510: INV-2026-0509 | B510: T0073 | C510: شركة هيثم للتجارة | D510: 708 | E510: 2026-08 | F510: 13000 | H510: غير محدد | K510: الإكسيل | L510: 46304

Sheet الصيانة
A1: كود الصيانة | B1: كود الوحدة | C1: المشروع | D1: الوحدة | E1: التاريخ | F1: النوع | G1: الوصف | H1: التكلفة | I1: يتحملها | J1: الحالة | K1: تاريخ الإغلاق | L1: ملاحظات | M1: تاريخ الإضافة | N1: المستأجر وقتها (محسوب) | O1: العقد وقتها (محسوب)

Sheet الإعدادات
A1: الإعداد | B1: القيمة | C1: الشرح
A2: اسم المكتب | B2: إيجاري | C2: يظهر أعلى الورقة والموقع
A3: أيام السماح بعد الاستحقاق | B3: 5 | C3: بعدها يُعتبر الشهر متأخرًا
A4: يوم الاستحقاق الافتراضي | B4: 1 | C4: يوم الشهر الذي يستحق فيه الإيجار ما لم يحدد العقد غيره
A5: عتبة الشغور الطويل (شهور) | B5: 3 | C5: الوحدة الشاغرة أطول من ذلك تظهر كتنبيه
A6: بداية المحاسبة (سنة-شهر) | B6: 2026-01 | C6: الشهور قبله لا تُحاسَب (بداية الورقة)
A7: الزيادة السنوية الافتراضية % | B7: 10 | C7: تُقترح عند إنشاء عقد جديد
A8: سنوات الورقة | B8: 2026 | C8: أوراق السنوات الموجودة (تُضاف تلقائيًا)
A9: بادئة رقم الفاتورة | B9: INV | C9: مثل INV-2026-0001
A10: العملة | B10: ج | C10: رمز العملة في العرض
A12: آخر كتابة من الموقع | B12: 2026-10-09 14:16:05
A13: إصدار البنية | B13: 2

Sheet سجل التعديلات
A1: الوقت | B1: العملية | C1: الكيان | D1: الكود | E1: التفاصيل
