Workbook

Sheet 2026
K1: 2026
A2: م | B2: المشروع | C2: الاسم | D2: الممثل القانوني | E2: الوحدة | F2: العنوان | G2: العقد من | H2: العقد الى | I2: تسجيل ضريبي | J2: الرقم القومي / الباسبور | K2: يناير | L2: فبراير | M2: مارس | N2: ابريل | O2: مايو | P2: يونيو | Q2: يوليو | R2: اغسطس | S2: سبتمبر | T2: اكتوبر | U2: نوفمبر | V2: ديسمبر | W2: الاجمالي | X2: ملاحظات
A3: 1 | B3: بابل | C3: عمرو أيمن زكي | D3: باسم رامي عبد الرحمن | E3: محل | F3: شارع بابل الدقي 39 | G3: 45078 | H3: 46173 | J3: 25138731744548 | K3: 12705 | L3: 12705 | M3: 12705 | N3: 12705 | O3: 12705 | W3: =SUM(K3:V3)
A4: 2 | B4: بابل | C4: شركة البركة للمقاولات | D4: عادل باسم عابدين | E4: محل | F4: شارع بابل الدقي 39 | G4: 45778 | H4: 46142 | J4: 20876376398458 | K4: 30500 | L4: 30500 | M4: 30500 | N4: 30500 | W4: =SUM(K4:V4)
A5: 3 | B5: بابل | C5: شركة الأفق لتكنولوجيا المعلومات | D5: سامح يوسف نصار | E5: ميزان 1/2 | F5: شارع بابل الدقي 39 | G5: 45432 | H5: 46526 | I5: 613-789-568 | J5: 26161169066883 | K5: 45100 | L5: 45100 | M5: 45100 | N5: 45100 | O5: 46603 | P5: 49610 | Q5: 49610 | R5: 49610 | W5: =SUM(K5:V5)
A6: 4 | B6: بابل | C6: شركة النور للإنتاج الفني | D6: نهى علي فوزي | E6: ميزان 3 | F6: شارع بابل الدقي 39 | G6: 45444 | H6: 46173 | J6: P95142580 | K6: 41800 | L6: 41800 | M6: 41800 | N6: 41800 | O6: 41800 | W6: =SUM(K6:V6)
A7: 5 | B7: بابل | C7: شركة الأفق لتكنولوجيا المعلومات | D7: أحمد ياسر منصور | E7: الدور الثاني | F7: شارع بابل الدقي 39 | G7: 45352 | H7: 46446 | I7: 613-789-568 | J7: 28134981129635 | K7: 83600 | L7: 83600 | M7: 91960 | N7: 91960 | O7: 91960 | P7: 91960 | Q7: 91960 | R7: 91960 | W7: =SUM(K7:V7)
A8: 6 | B8: بابل | C8: شركة الأمل للاستشارات الهندسية | D8: أحمد ياسر منصور | E8: مكتب 42 | F8: شارع بابل الدقي 39 | G8: 45158 | H8: 46253 | I8: 644-353-356 | J8: 28134981129635 | K8: 30250 | L8: 30250 | M8: 30250 | N8: 30250 | O8: 30250 | P8: 30250 | Q8: 30250 | R8: 44090 | W8: =SUM(K8:V8)
A9: 7 | B9: بابل | C9: عمرو إبراهيم فوزي | D9: عمرو إبراهيم فوزي | E9: مكتب 61 | F9: شارع بابل الدقي 39 | G9: 45017 | H9: 46112 | J9: 23761205972580 | K9: 24330 | L9: 24330 | M9: 24330 | W9: =SUM(K9:V9)
A10: 8 | B10: محيي الدين | C10: شركة المستقبل للتدريب | D10: مروان خالد بدوي | E10: ميزان 1 | F10: شارع محيي الدين ابو العز 30 | G10: 45139 | H10: 46965 | I10: 979-738-984 | J10: 28108914237679 | K10: 42350 | L10: 42350 | M10: 42350 | N10: 42350 | O10: 42350 | P10: 42350 | Q10: 42350 | R10: 46585 | W10: =SUM(K10:V10)
A11: 9 | B11: محيي الدين | C11: شركة الياسمين للتجارة | D11: ياسر محمد رشاد | E11: ميزان 2 | F11: شارع محيي الدين ابو العز 30 | G11: 45242 | H11: 46337 | I11: 738-017-798 | J11: 21743589223868 | K11: 25410 | L11: 25410 | M11: 25410 | N11: 25410 | O11: 25410 | P11: 25410 | Q11: 25410 | R11: 25410 | W11: =SUM(K11:V11)
A12: 10 | B12: محيي الدين | C12: شركة الأفق للاستيراد والتصدير | D12: أمير فادي منصور | E12: 202 | F12: شارع محيي الدين ابو العز 30 | G12: 45231 | H12: 46326 | I12: 829-102-559 | J12: N956207298 | K12: 46585 | L12: 46585 | M12: 46585 | N12: 46585 | O12: 46585 | P12: 46585 | Q12: 46585 | R12: 46585 | W12: =SUM(K12:V12)
A13: 11 | B13: محيي الدين | C13: شريف هشام فوزي | D13: شريف هشام فوزي | E13: 301 | F13: شارع محيي الدين ابو العز 30 | G13: 46143 | H13: 46507 | J13: 26443030301781 | K13: 22990 | L13: 22990 | M13: 22990 | N13: 22990 | O13: 37000 | P13: 37000 | Q13: 37000 | R13: 37000 | W13: =SUM(K13:V13)
A14: 12 | B14: محيي الدين | C14: د/ باسم أمير سليم | D14: د/ باسم أمير سليم | E14: 302 | F14: شارع محيي الدين ابو العز 30 | G14: 46143 | H14: 46507 | J14: 23152474861518 | K14: 35000 | L14: 35000 | M14: 35000 | N14: 35000 | O14: 38500 | P14: 38500 | Q14: 38500 | R14: 37500 | W14: =SUM(K14:V14)
A15: 13 | B15: محيي الدين | C15: شركة الصفوة للإنتاج الفني | D15: خالد يوسف شاكر | E15: 303 | F15: شارع محيي الدين ابو العز 30 | G15: 45870 | H15: 46965 | I15: 963-271-933 | J15: 23918025447827 | K15: 43000 | L15: 43000 | M15: 43000 | N15: 43000 | O15: 43000 | P15: 43000 | Q15: 43000 | R15: 49450 | W15: =SUM(K15:V15)
A16: 14 | B16: محيي الدين | C16: شركة الصفوة للإنتاج الفني | D16: خالد يوسف شاكر | E16: 304 | F16: شارع محيي الدين ابو العز 30 | G16: 45474 | H16: 46568 | I16: 917-062-564 | J16: 23918025447827 | K16: 25300 | L16: 25300 | M16: 25300 | N16: 25300 | O16: 25300 | P16: 25300 | Q16: 27830 | R16: 27830 | W16: =SUM(K16:V16)
A17: 15 | B17: محيي الدين | C17: د/ يوسف حسن مكرم | D17: خالد نادر الجندي | E17: 401 | F17: شارع محيي الدين ابو العز 30 | G17: 45668 | H17: 46397 | J17: 27097993904905 | K17: 36025 | L17: 37665 | M17: 37665 | N17: 37665 | O17: 37665 | P17: 37665 | Q17: 37665 | R17: 37665 | W17: =SUM(K17:V17)
A18: 16 | B18: محيي الدين | C18: د/ فادي سعيد منصور | D18: أيمن حسين عبد الرحمن | E18: 404 | F18: شارع محيي الدين ابو العز 30 | G18: 45292 | H18: 46387 | J18: 20471368514380 | K18: 30250 | L18: 30250 | M18: 30250 | N18: 30250 | O18: 30250 | P18: 30250 | Q18: 30250 | R18: 30250 | W18: =SUM(K18:V18)
A19: 17 | B19: محيي الدين | C19: د/ رضوى خالد عبد الرحمن | D19: د/ رضوى خالد عبد الرحمن | E19: 502 | F19: شارع محيي الدين ابو العز 30 | G19: 45170 | H19: 46265 | J19: 25947450186407 | K19: 19060 | L19: 19060 | M19: 19060 | N19: 19060 | O19: 19060 | P19: 19060 | Q19: 19060 | R19: 19060 | W19: =SUM(K19:V19)
A20: 18 | B20: محيي الدين | C20: د/ آية أيمن بدوي | D20: هالة إبراهيم سليم | E20: 503 | F20: شارع محيي الدين ابو العز 30 | G20: 45200 | H20: 46295 | J20: 22497066998665 | K20: 20570 | L20: 20570 | M20: 20570 | N20: 20570 | O20: 20570 | P20: 20570 | Q20: 20570 | R20: 20570 | W20: =SUM(K20:V20)
A21: 19 | B21: محيي الدين | C21: محمد سعيد عبد الرحمن | D21: محمد سعيد عبد الرحمن | E21: 504 | F21: شارع محيي الدين ابو العز 30 | G21: 45231 | H21: 46326 | J21: 26334081585080 | K21: 25410 | L21: 25410 | M21: 25410 | N21: 25410 | O21: 25410 | P21: 25410 | Q21: 25410 | R21: 25410 | W21: =SUM(K21:V21)
A22: 20 | B22: ابو بكر | C22: شركة الأمل للإنتاج الفني | D22: حسين إبراهيم حسنين | E22: ميزان 1 | F22: شارع ابو بكر الصديق 3 | G22: 45505 | H22: 46599 | I22: 554-940-596 | J22: 21677613365039 | K22: 40700 | L22: 40700 | M22: 40700 | N22: 40700 | O22: 40700 | P22: 40700 | Q22: 40700 | R22: 44770 | W22: =SUM(K22:V22)
A23: 21 | B23: ابو بكر | C23: شركة النور للاستشارات الهندسية | D23: حسين إبراهيم حسنين | E23: ميزان 2 | F23: شارع ابو بكر الصديق 3 | G23: 45505 | H23: 46599 | I23: 024-154-399 | J23: 21677613365039 | K23: 40700 | L23: 40700 | M23: 40700 | N23: 40700 | O23: 40700 | P23: 40700 | Q23: 40700 | R23: 44770 | W23: =SUM(K23:V23)
A24: 22 | B24: ابو بكر | C24: عادل عمر مكرم | D24: عادل عمر مكرم | E24: 102 | F24: شارع ابو بكر الصديق 3 | G24: 46204 | H24: 46568 | J24: P67585839 | K24: 17500 | L24: 17500 | M24: 17500 | N24: 17500 | O24: 17500 | P24: 17500 | Q24: 20000 | R24: 20000 | W24: =SUM(K24:V24)
A25: 23 | B25: ابو بكر | C25: تامر علي بدوي | D25: تامر علي بدوي | E25: 103 | F25: شارع ابو بكر الصديق 3 | G25: 45992 | H25: 46356 | J25: 21316304221599 | K25: 7000 | L25: 7000 | M25: 7000 | N25: 7000 | O25: 7000 | P25: 7000 | Q25: 7000 | R25: 7000 | W25: =SUM(K25:V25)
A26: 24 | B26: ابو بكر | C26: مروان محمود حسنين | D26: مروان محمود حسنين | E26: 104 | F26: شارع ابو بكر الصديق 3 | G26: 46204 | H26: 46568 | J26: X488802 | K26: 13000 | L26: 13000 | M26: 13000 | N26: 13000 | O26: 13000 | P26: 13000 | Q26: 15000 | R26: 15000 | W26: =SUM(K26:V26)
A27: 25 | B27: ابو بكر | C27: عادل عمر مكرم | D27: عادل عمر مكرم | E27: 105 | F27: شارع ابو بكر الصديق 3 | G27: 46204 | H27: 46568 | J27: P16126721 | K27: 13500 | L27: 13500 | M27: 13500 | N27: 13500 | O27: 13500 | P27: 13500 | Q27: 15000 | R27: 1000 | W27: =SUM(K27:V27)
A28: 26 | B28: ابو بكر | C28: حسين أمير بدوي | D28: حسين أمير بدوي | E28: 106 | F28: شارع ابو بكر الصديق 3 | G28: 45992 | H28: 46356 | J28: 29005091319585 | K28: 7000 | L28: 7000 | M28: 7000 | N28: 7000 | O28: 7000 | P28: 7000 | Q28: 7000 | R28: 7000 | W28: =SUM(K28:V28)
A29: 27 | B29: ابو بكر | C29: حسين أمير بدوي | D29: حسين أمير بدوي | E29: 107 | F29: شارع ابو بكر الصديق 3 | G29: 46204 | H29: 46568 | J29: 29005091319585 | K29: 6000 | L29: 6000 | M29: 6000 | N29: 6000 | O29: 6000 | P29: 8000 | Q29: 8000 | R29: 8000 | W29: =SUM(K29:V29)
A30: 28 | B30: ابو بكر | C30: حسين أمير بدوي | D30: حسين أمير بدوي | E30: 108 | F30: شارع ابو بكر الصديق 3 | G30: 46204 | H30: 46568 | J30: 29005091319585 | K30: 6000 | L30: 6000 | M30: 6000 | N30: 6000 | O30: 6000 | P30: 8000 | Q30: 8000 | R30: 8000 | W30: =SUM(K30:V30)
A31: 29 | B31: ابو بكر | C31: شركة الأفق للتدريب | D31: رضوى أيمن البنا | E31: 201 | F31: شارع ابو بكر الصديق 3 | G31: 45078 | H31: 46173 | J31: 24376235169264 | K31: 11495 | L31: 11495 | M31: 11495 | N31: 11495 | O31: 11495 | W31: =SUM(K31:V31)
A32: 30 | B32: ابو بكر | C32: د/ نادر شريف شاكر | D32: هاني فادي الشريف | E32: 202 | F32: شارع ابو بكر الصديق 3 | G32: 45901 | H32: 46265 | J32: 23662595948884 | K32: 16500 | L32: 16500 | M32: 16500 | N32: 16500 | O32: 16500 | P32: 16500 | Q32: 16500 | R32: 16500 | W32: =SUM(K32:V32)
A33: 31 | B33: ابو بكر | C33: د/ يوسف خالد الخولي | D33: علي عمرو غانم | E33: 204 | F33: شارع ابو بكر الصديق 3 | G33: 45839 | H33: 46203 | J33: 27385486153673 | K33: 12500 | L33: 12500 | M33: 12500 | N33: 12500 | O33: 12500 | P33: 12500 | W33: =SUM(K33:V33)
A34: 32 | B34: ابو بكر | C34: د/ عمر باسم رزق | D34: طارق حسن زكي | E34: 204 | F34: شارع ابو بكر الصديق 3 | G34: 46204 | H34: 46568 | J34: 21773257847648 | Q34: 14500 | R34: 14500 | W34: =SUM(K34:V34)
A35: 33 | B35: ابو بكر | C35: أحمد عمرو سليم | D35: أحمد عمرو سليم | E35: 205 | F35: شارع ابو بكر الصديق 3 | G35: 45977 | H35: 46341 | J35: N669822642 | K35: 14000 | L35: 14000 | M35: 14000 | N35: 14000 | O35: 14000 | P35: 14000 | Q35: 14000 | R35: 14000 | W35: =SUM(K35:V35)
A36: 34 | B36: ابو بكر | C36: شركة النخبة للتجارة | D36: آية سامح غانم | E36: 206 | F36: شارع ابو بكر الصديق 3 | G36: 45901 | H36: 46264 | J36: 21663141681918 | K36: 16500 | L36: 16500 | M36: 16500 | N36: 16500 | O36: 16500 | P36: 16500 | Q36: 16500 | R36: 16500 | W36: =SUM(K36:V36)
A37: 35 | B37: ابو بكر | C37: د/ رنا هشام رزق | D37: شيماء عادل البنا | E37: 207 | F37: شارع ابو بكر الصديق 3 | G37: 46143 | H37: 46507 | J37: P59909132 | O37: 20000 | P37: 20000 | Q37: 20000 | R37: 20000 | W37: =SUM(K37:V37)
A38: 36 | B38: ابو بكر | C38: شركة النخبة للإنتاج الفني | D38: نادر فادي حجازي | E38: 208 | F38: شارع ابو بكر الصديق 3 | G38: 45383 | H38: 46477 | I38: 007-132-345 | J38: 26108998543202 | K38: 19250 | L38: 19250 | M38: 19250 | N38: 21175 | O38: 21175 | P38: 21175 | Q38: 21175 | R38: 21175 | W38: =SUM(K38:V38)
A39: 37 | B39: ابو بكر | C39: أحمد طارق غانم | D39: أحمد طارق غانم | E39: 301 | F39: شارع ابو بكر الصديق 3 | G39: 45920 | H39: 46284 | J39: 25580455031010 | K39: 17000 | L39: 17000 | M39: 17000 | N39: 17000 | O39: 17000 | W39: =SUM(K39:V39)
A40: 38 | B40: ابو بكر | C40: خالد شريف زكي | D40: خالد شريف زكي | E40: 302 | F40: شارع ابو بكر الصديق 3 | G40: 45916 | H40: 46280 | I40: 402-661-896 | J40: 27848778987415 | K40: 17000 | L40: 17000 | M40: 17000 | N40: 17000 | O40: 17000 | P40: 17000 | Q40: 17000 | R40: 17000 | W40: =SUM(K40:V40)
...

Sheet ملخص المشاريع
A1: المشروع | B1: عدد الوحدات | C1: الاجمالي
A2: بابل | B2: =COUNTIF('2026'!B3:B75,A2) | C2: =SUMIF('2026'!B3:B75,A2,'2026'!W3:W75)
A3: محيي الدين | B3: =COUNTIF('2026'!B3:B75,A3) | C3: =SUMIF('2026'!B3:B75,A3,'2026'!W3:W75)
A4: ابو بكر | B4: =COUNTIF('2026'!B3:B75,A4) | C4: =SUMIF('2026'!B3:B75,A4,'2026'!W3:W75)
A5: الاجمالي | B5: =SUM(B2:B4) | C5: =SUM(C2:C4)
